<?xml version="1.0"?>
<robot xmlns:xacro="http://www.ros.org/wiki/xacro"  name="obot">

    <material name="white">
        <color rgba="1 1 1 1" />
    </material>

    <material name="grey">
        <color rgba="0.25 0.25 0.25 1"/>
    </material>

    <material name="orange">
        <color rgba="1 0.55 0 1"/>
    </material>

    <material name="blue">
        <color rgba="0.2 0.2 1 1"/>
    </material>

    <material name="black">
        <color rgba="0.1 0.1 0.1 1"/>
    </material>

    <material name="silver">
        <color rgba="0.6 0.6 0.6 1"/>
    </material>




    <xacro:property name="slab_height" value="0.3"/>
    <xacro:property name="gazebo_visual" value="true"/>

    <xacro:arg name="laser_visual" default="false"/>
    <xacro:arg name="imu_visual"   default="true"/>
    <xacro:arg name="sonar_visual"   default="false"/>
    <xacro:arg name="cam_visual"   default="false"/>



    <xacro:include filename="$(find obot_description)/description/inertia_macros.xacro"/>
    <xacro:include filename="$(find obot_description)/description/part_macros.xacro"/>
    


    



    <!-- BASE LINK -->

    <!-- <base joint/> -->
    <link name="base_link">  
    </link>

    <!-- ################# -->





    <!-- CHASSIS LINK -->

    <joint name="chassis_joint" type="fixed">
        <parent link="base_link"/>
        <child link="chassis_link"/>
        <origin xyz="0 0 0.05"/>
    </joint>

    <link name="chassis_link">
        <visual>
            <origin xyz="0 0 0" rpy="0 0 0"/>
            <geometry>
                <xacro:unless value="${gazebo_visual}">
                    <mesh filename="package://obot_description/meshes/chassis.stl"/>
                </xacro:unless>
                <xacro:if value="${gazebo_visual}">
                    <mesh filename="$(find obot_description)/meshes/chassis.stl"/>
                </xacro:if>  
            </geometry>
            <material name="orange"/>
        </visual>

        <collision>
            <origin xyz="0 0 0.075" rpy="0 0 0"/>
            <geometry>
                <cylinder radius="0.2" length="0.15"/>
            </geometry>
        </collision>

        <xacro:inertial_cylinder mass="10" length="0.15" radius="0.2">
            <origin xyz="0 0 0.075" rpy="0 0 0"/>
        </xacro:inertial_cylinder>
    </link>

    <gazebo reference="chassis_link">
        <material>Gazebo/Orange</material>
    </gazebo>

    <!--  ########################### -->







    <xacro:include filename="$(find obot_description)/description/add_slab_macros.xacro"/>








    <!-- LEFT WHEEL LINK FRAME -->

    <joint name="left_wheel_joint" type="continuous">
        <parent link="chassis_link"/>
        <child link="left_wheel_link"/>
        <origin xyz="0 0.2 0" rpy="${-pi/2} 0 0"/>
        <axis xyz="0 0 1"/>
    </joint>

    <link name="left_wheel_link">
        <xacro:insert_drive_wheel_link/>
    </link>

    <gazebo reference="left_wheel_link">
        <mu1>1.0</mu1>
        <mu2>1.0</mu2>
        <!-- <kp>1000000.0</kp>
        <kd>1.0</kd>
        <fdir1>1 0 0</fdir1>
        <minDepth>0.1</minDepth> -->
        <material>Gazebo/FlatBlack</material>
    </gazebo>

    <!--  ########################### -->







    <!-- RIGHT WHEEL LINK FRAME -->

    <joint name="right_wheel_joint" type="continuous">
        <parent link="chassis_link"/>
        <child link="right_wheel_link"/>
        <origin xyz="0 -0.2 0" rpy="${-pi/2} 0 0"/>
        <axis xyz="0 0 1"/>
    </joint>

    <link name="right_wheel_link">
        <xacro:insert_drive_wheel_link/>
    </link>

    <gazebo reference="right_wheel_link">
        <mu1>1.0</mu1>
        <mu2>1.0</mu2>
        <!-- <kp>1000000.0</kp>
        <kd>1.0</kd>
        <fdir1>1 0 0</fdir1>
        <minDepth>0.1</minDepth> -->
        <material>Gazebo/FlatBlack</material>
    </gazebo>

    <!--  ########################### -->








    <!-- FRONT CASTER HOLDER LINK FRAME -->

    <joint name="front_caster_holder_joint" type="continuous">
        <parent link="chassis_link"/>
        <child link="front_caster_holder_link"/>
        <origin xyz="0.16 0 0" rpy="0 0 0"/>
        <axis xyz="0 0 1"/>
        <dynamics friction="0.0100" />
    </joint>

    <link name="front_caster_holder_link">
        <xacro:insert_caster_holder_link/>
    </link>

    <gazebo reference="front_caster_holder_link">
        <mu1>0.01</mu1>
        <mu2>0.01</mu2>
        <!-- <kp>${wheel_kp}</kp>
        <kd>${wheel_kd}</kd>
        <dampingFactor>${wheel_df}</dampingFactor>
        <fdir1>1 0 0</fdir1> -->
        <material>Gazebo/Silver</material>
    </gazebo>

    <!-- ########################################## -->








    <!-- FRONT CASTER WHEEL LINK FRAME -->

    <joint name="front_caster_wheel_joint" type="continuous">
        <parent link="front_caster_holder_link"/>
        <child link="front_caster_wheel_link"/>
        <origin xyz="0.016 0 -0.031" rpy="${-pi/2} 0 0"/>
        <axis xyz="0 0 1"/>
    </joint>

    <link name="front_caster_wheel_link">
        <xacro:insert_caster_wheel_link/>
    </link>

    <gazebo reference="front_caster_wheel_link">
        <mu1>1.0</mu1>
        <mu2>1.0</mu2>
        <!-- <kp>${wheel_kp}</kp>
        <kd>${wheel_kd}</kd>
        <dampingFactor>${wheel_df}</dampingFactor> -->
        <fdir1>1 0 0</fdir1>
        <material>Gazebo/FlatBlack</material>
    </gazebo>

    <!-- ########################################## -->









    <!-- REAR CASTER HOLDER LINK FRAME -->

    <joint name="rear_caster_holder_joint" type="continuous">
        <parent link="chassis_link"/>
        <child link="rear_caster_holder_link"/>
        <origin xyz="-0.16 0 0" rpy="0 0 0"/>
        <axis xyz="0 0 1"/>
        <dynamics friction="0.0100" />
    </joint>

    <link name="rear_caster_holder_link">
        <xacro:insert_caster_holder_link/>
    </link>

    <gazebo reference="rear_caster_holder_link">
        <mu1>0.01</mu1>
        <mu2>0.01</mu2>
        <!-- <kp>${wheel_kp}</kp>
        <kd>${wheel_kd}</kd>
        <dampingFactor>${wheel_df}</dampingFactor>
        <fdir1>1 0 0</fdir1> -->
        <material>Gazebo/Silver</material>
    </gazebo>

    <!-- ####################################### -->








    <!-- REAR CASTER WHEEL LINK FRAME -->

    <joint name="rear_caster_wheel_joint" type="continuous">
        <parent link="rear_caster_holder_link"/>
        <child link="rear_caster_wheel_link"/>
        <origin xyz="0.016 0 -0.031" rpy="${-pi/2} 0 0"/>
        <axis xyz="0 0 1"/>
    </joint>

    <link name="rear_caster_wheel_link">
        <xacro:insert_caster_wheel_link/>
    </link>

    <gazebo reference="rear_caster_wheel_link">
        <mu1>1.0</mu1>
        <mu2>1.0</mu2>
        <!-- <kp>${wheel_kp}</kp>
        <kd>${wheel_kd}</kd>
        <dampingFactor>${wheel_df}</dampingFactor> -->
        <fdir1>1 0 0</fdir1>
        <material>Gazebo/FlatBlack</material>
    </gazebo>

    <!-- ##################################### -->






    <xacro:include filename="$(find obot_description)/description/controllers.xacro"/>






    <xacro:include filename="$(find obot_description)/description/sensors/imu.xacro"/>
    <xacro:include filename="$(find obot_description)/description/sensors/lidar.xacro"/>
    <xacro:include filename="$(find obot_description)/description/sensors/cam.xacro"/>
    <xacro:include filename="$(find obot_description)/description/sensors/sonar.xacro"/>


  
</robot>